Workbook

Sheet MAR INVEST
A1: MAR INVEST — SIMULADOR DE INVESTIMENTOS
A4: DADOS DO INVESTIDOR
A5: PERFIL DE INVESTIDOR | B5: Conservador
A6: SALÁRIO MENSAL | B6: 5000
A7: PERCENTUAL SUGERIDO PARA INVESTIMENTO | B7: 0.3
A8: PRAZO DO INVESTIMENTO | B8: 10 | C8: ANOS
A10: INVESTIMENTO MENSAL | B10: 200
A11: PRAZO EM MESES | B11: =B8*12 -> 120
A12: PATRIMÔNIO ACUMULADO | B12: =FV('BASE DO SIMULADOR'!B40,B11,-B10,0,0) -> 40043.494
A13: TOTAL INVESTIDO | B13: =B10*B11 -> 24000
A14: RENDIMENTOS ACUMULADOS | B14: =B12-B13 -> 16043.494
A15: DIVIDENDOS MENSAIS ESTIMADOS | B15: =B12*'BASE DO SIMULADOR'!B41 -> 200.21747
A17: COMPOSIÇÃO DA CARTEIRA
A18: TIPO DE FUNDO | B18: PERCENTUAL | C18: VALOR MENSAL
A19: PAPEL | B19: =INDEX('BASE DO SIMULADOR'!$B$5:$D$10,MATCH(A19,'BASE DO SIMULADOR'!$A$5:$A$10,0),MATCH($B$5,'BASE DO SIMULADOR'!$B$4:$D$4,0)) -> 0.5 | C19: =B19*$B$10 -> 100
A20: TIJOLO | B20: =INDEX('BASE DO SIMULADOR'!$B$5:$D$10,MATCH(A20,'BASE DO SIMULADOR'!$A$5:$A$10,0),MATCH($B$5,'BASE DO SIMULADOR'!$B$4:$D$4,0)) -> 0.3 | C20: =B20*$B$10 -> 60
A21: HÍBRIDOS | B21: =INDEX('BASE DO SIMULADOR'!$B$5:$D$10,MATCH(A21,'BASE DO SIMULADOR'!$A$5:$A$10,0),MATCH($B$5,'BASE DO SIMULADOR'!$B$4:$D$4,0)) -> 0.2 | C21: =B21*$B$10 -> 40
A22: FOFs | B22: =INDEX('BASE DO SIMULADOR'!$B$5:$D$10,MATCH(A22,'BASE DO SIMULADOR'!$A$5:$A$10,0),MATCH($B$5,'BASE DO SIMULADOR'!$B$4:$D$4,0)) -> 0 | C22: =B22*$B$10 -> 0
A23: DESENVOLVIMENTO | B23: =INDEX('BASE DO SIMULADOR'!$B$5:$D$10,MATCH(A23,'BASE DO SIMULADOR'!$A$5:$A$10,0),MATCH($B$5,'BASE DO SIMULADOR'!$B$4:$D$4,0)) -> 0 | C23: =B23*$B$10 -> 0
A24: HOTELARIA | B24: =INDEX('BASE DO SIMULADOR'!$B$5:$D$10,MATCH(A24,'BASE DO SIMULADOR'!$A$5:$A$10,0),MATCH($B$5,'BASE DO SIMULADOR'!$B$4:$D$4,0)) -> 0 | C24: =B24*$B$10 -> 0
A25: TOTAL | B25: =SUM(B19:B24) -> 1 | C25: =SUM(C19:C24) -> 200
A28: PROJEÇÃO DE INVESTIMENTO
A29: APORTE MENSAL | B29: =B10 -> 200
A30: TOTAL INVESTIDO | B30: =B13 -> 24000
A31: RENDIMENTOS ACUMULADOS | B31: =B14 -> 16043.494
A32: PATRIMÔNIO ACUMULADO | B32: =B12 -> 40043.494
A33: DIVIDENDOS MENSAIS ESTIMADOS | B33: =B15 -> 200.21747
A34: RENDIMENTO SOBRE O TOTAL INVESTIDO | B34: =B14/B13 -> 0.66847891
A36: CENÁRIOS DE INVESTIMENTO
A37: CENÁRIO | B37: TOTAL INVESTIDO | C37: DIVIDENDOS MENSAIS
A38: Quanto em 1 ano? | B38: =B10*'BASE DO SIMULADOR'!C30 -> 2400 | C38: =FV('BASE DO SIMULADOR'!B40,'BASE DO SIMULADOR'!C30,-B10,0,0)*'BASE DO SIMULADOR'!B41 -> 12.542337
A39: Quanto em 3 anos? | B39: =B10*'BASE DO SIMULADOR'!C31 -> 7200 | C39: =FV('BASE DO SIMULADOR'!B40,'BASE DO SIMULADOR'!C31,-B10,0,0)*'BASE DO SIMULADOR'!B41 -> 41.52873
A40: Quanto em 5 anos? | B40: =B10*'BASE DO SIMULADOR'!C32 -> 12000 | C40: =FV('BASE DO SIMULADOR'!B40,'BASE DO SIMULADOR'!C32,-B10,0,0)*'BASE DO SIMULADOR'!B41 -> 76.623867
A41: Quanto em 7 anos? | B41: =B10*'BASE DO SIMULADOR'!C33 -> 16800 | C41: =FV('BASE DO SIMULADOR'!B40,'BASE DO SIMULADOR'!C33,-B10,0,0)*'BASE DO SIMULADOR'!B41 -> 119.11514
A42: Quanto em 10 anos? | B42: =B10*'BASE DO SIMULADOR'!C34 -> 24000 | C42: =FV('BASE DO SIMULADOR'!B40,'BASE DO SIMULADOR'!C34,-B10,0,0)*'BASE DO SIMULADOR'!B41 -> 200.21747

Sheet BASE DO SIMULADOR
A1: BASE DO SIMULADOR
A3: PERFIS DE INVESTIDOR
A4: TIPO DE FUNDO | B4: CONSERVADOR | C4: MODERADO | D4: AGRESSIVO
A5: PAPEL | B5: 0.5 | C5: 0.3 | D5: 0.15
A6: TIJOLO | B6: 0.3 | C6: 0.25 | D6: 0.25
A7: HÍBRIDOS | B7: 0.2 | C7: 0.2 | D7: 0.2
A8: FOFs | B8: 0 | C8: 0.1 | D8: 0.15
A9: DESENVOLVIMENTO | B9: 0 | C9: 0.05 | D9: 0.1
A10: HOTELARIA | B10: 0 | C10: 0.1 | D10: 0.15
A11: TOTAL | B11: =SUM(B5:B10) -> 1 | C11: =SUM(D5:D10) -> 1 | D11: =SUM(D5:D10) -> 1
A14: CLASSIFICAÇÃO DAS ESTRATÉGIAS
A15: TIPO DE FUNDO | B15: NÍVEL DE EXPOSIÇÃO
A16: PAPEL | B16: 1
A17: TIJOLO | B17: 2
A18: HÍBRIDOS | B18: 2
A19: FOFs | B19: 2
A20: DESENVOLVIMENTO | B20: 3
A21: HOTELARIA | B21: 3
A23: 1 — Menor exposição relativa ao risco
A24: 2 — Exposição intermediária
A25: 3 — Maior exposição relativa ao risco
A28: CENÁRIOS
A29: CENÁRIO | B29: PRAZO (ANOS) | C29: PRAZO (MESES)
A30: CENÁRIO 1 | B30: 1 | C30: 12
A31: CENÁRIO 2 | B31: 3 | C31: 36
A32: CENÁRIO 3 | B32: 5 | C32: 60
A33: CENÁRIO 4 | B33: 7 | C33: 84
A34: CENÁRIO 5 | B34: 10 | C34: 120
A37: PREMISSAS DO SIMULADOR
A38: PARÂMETRO | B38: VALOR
A39: PERCENTUAL SUGERIDO DO SALÁRIO | B39: 0.3
A40: RENDIMENTO DA CARTEIRA | B40: 0.008
A41: TAXA DE DISTRIBUIÇÃO ESTIMADA | B41: 0.005
A42: PERIODICIDADE DOS APORTES | B42: MENSAL
A45: NOTAS METODOLÓGICAS
A46: Classificação meramente ilustrativa, baseada nas características gerais das estratégias. O risco efetivo depende da composição da carteira, política de investimento, gestão e condições de mercado.
A47: As proporções utilizadas nos perfis são parâmetros ilustrativos desenvolvidos exclusivamente para a simulação.
A50: ÁREA DE CÁLCULOS
A51: PARÂMETRO | B51: VALOR
A52: INVESTIMENTO MENSAL | B52: 200
...
